<?xml version="1.0" ?>
<!-- =================================================================================== -->
<!-- |    This document was autogenerated by xacro from rastreator.xacro               | -->
<!-- |    EDITING THIS FILE BY HAND IS NOT RECOMMENDED                                 | -->
<!-- =================================================================================== -->
<robot name="rastreator" xmlns:xacro="http://www.ros.org/wiki/xacro">
  <!--**************************************************************-->
  <!--MATERIAL COLOUR-->
  <!--**************************************************************-->
  <material name="dark">
    <color rgba="0.3 0.3 0.3 1.0"/>
  </material>
  <material name="black">
    <color rgba="0.0 0.0 0.0 1.0"/>
  </material>
  <material name="light_black">
    <color rgba="0.4 0.4 0.4 1.0"/>
  </material>
  <!--**************************************************************-->
  <!--DUMMY LINK (without inertia)-->
  <!--**************************************************************-->
  <link name="base_footprint"/>
  <!--**************************************************************-->
  <!--CHASSIS (base link)-->
  <!--**************************************************************-->
  <link name="base_link">
    <inertial>
      <mass value="1.0"/>
      <inertia ixx="0.004677416666666667" ixy="0.0" ixz="0.0" iyy="0.0030244166666666666" iyz="0.0" izz="0.005013666666666667"/>
    </inertial>
    <!--COLLISION-->
    <collision>
      <geometry>
        <mesh filename="package://rastreator_description/mesh/rastreator_chassis.stl" scale="0.001 0.001 0.001"/>
      </geometry>
    </collision>
    <!--VISUAL-->
    <visual>
      <geometry>
        <mesh filename="package://rastreator_description/mesh/rastreator_chassis.stl" scale="0.001 0.001 0.001"/>
      </geometry>
      <material name="light_black"/>
    </visual>
  </link>
  <!--JOINT-->
  <joint name="base_joint" type="fixed">
    <origin rpy="0 0 0" xyz="0.0 0.0 0.0235"/>
    <parent link="base_footprint"/>
    <child link="base_link"/>
  </joint>
  <!--**************************************************************-->
  <!--LEFT WHEEL-->
  <!--**************************************************************-->
  <link name="left_wheel_link">
    <inertial>
      <mass value="0.15"/>
      <inertia ixx="4.3659375e-05" ixy="0" ixz="0" iyy="4.3659375e-05" iyz="0" izz="7.921875e-05"/>
    </inertial>
    <!--COLLISION-->
    <collision>
      <geometry>
        <mesh filename="package://rastreator_description/mesh/rastreator_left_wheel.stl" scale="0.001 0.001 0.001"/>
      </geometry>
    </collision>
    <!--VISUAL-->
    <visual>
      <geometry>
        <mesh filename="package://rastreator_description/mesh/rastreator_left_wheel.stl" scale="0.001 0.001 0.001"/>
      </geometry>
      <material name="black"/>
    </visual>
  </link>
  <!--JOINT-->
  <joint name="wheel_left_joint" type="continuous">
    <origin rpy="0 0 0" xyz="-0.075 0.076 0.01501"/>
    <child link="left_wheel_link"/>
    <parent link="base_link"/>
    <axis rpy="0 0 0" xyz="0 1 0"/>
  </joint>
  <!--**************************************************************-->
  <!--RIGHT WHEEL-->
  <!--**************************************************************-->
  <link name="right_wheel_link">
    <inertial>
      <mass value="0.15"/>
      <inertia ixx="4.3659375e-05" ixy="0" ixz="0" iyy="4.3659375e-05" iyz="0" izz="7.921875e-05"/>
    </inertial>
    <!--COLLISION-->
    <collision>
      <geometry>
        <mesh filename="package://rastreator_description/mesh/rastreator_right_wheel.stl" scale="0.001 0.001 0.001"/>
      </geometry>
    </collision>
    <!--VISUAL-->
    <visual>
      <geometry>
        <mesh filename="package://rastreator_description/mesh/rastreator_right_wheel.stl" scale="0.001 0.001 0.001"/>
      </geometry>
      <material name="black"/>
    </visual>
  </link>
  <!--JOINT-->
  <joint name="wheel_right_joint" type="continuous">
    <origin rpy="0 0 0" xyz="-0.075 -0.081 0.01501"/>
    <child link="right_wheel_link"/>
    <parent link="base_link"/>
    <axis rpy="0 0 0" xyz="0 1 0"/>
  </joint>
  <!--**************************************************************-->
  <!--CASTER WHEEL (NOT VISUAL)-->
  <!--**************************************************************-->
  <link name="caster_front_link">
    <!--INERTIA-->
    <!--Not calling macro, just small values-->
    <inertial>
      <mass value="0.005"/>
      <inertia ixx="0.001" ixy="0.0" ixz="0.0" iyy="0.001" iyz="0.0" izz="0.001"/>
    </inertial>
    <!--COLLISION-->
    <collision>
      <geometry>
        <mesh filename="package://rastreator_description/mesh/caster_wheel.stl" scale="0.001 0.001 0.001"/>
      </geometry>
    </collision>
    <!--VISUAL-->
    <visual>
      <geometry>
        <mesh filename="package://rastreator_description/mesh/caster_wheel.stl" scale="0.001 0.001 0.001"/>
      </geometry>
      <material name="black"/>
    </visual>
  </link>
  <!--JOINT-->
  <joint name="caster_front_joint" type="fixed">
    <parent link="base_link"/>
    <child link="caster_front_link"/>
    <origin rpy="0 0 0" xyz="0 0 0"/>
  </joint>
  <!--**************************************************************-->
  <!--LASER/LIDAR-->
  <!--**************************************************************-->
  <link name="sensor_laser">
    <!--INERTIA-->
    <inertial>
      <inertia ixx="0" ixy="0" ixz="0" iyy="0" iyz="0" izz="0"/>
      <mass value="0.1"/>
    </inertial>
    <!--COLLISION-->
    <collision>
      <geometry>
        <mesh filename="package://rastreator_description/mesh/rplidar_a3.stl" scale="0.001 0.001 0.001"/>
      </geometry>
    </collision>
    <gravity>false</gravity>
    <!--VISUAL-->
    <visual>
      <geometry>
        <mesh filename="package://rastreator_description/mesh/rplidar_a3.stl" scale="0.001 0.001 0.001"/>
      </geometry>
      <material name="dark"/>
    </visual>
  </link>
  <!--JOINT-->
  <joint name="sensor_laser_joint" type="fixed">
    <origin rpy="0 0.0 0" xyz="0.0 0.0 0.132"/>
    <child link="sensor_laser"/>
    <parent link="base_link"/>
  </joint>
  <!--**************************************************************-->
  <!--IMU-->
  <!--**************************************************************-->
  <link name="imu_link">
    <!--COLLISION-->
    <collision>
      <geometry>
        <mesh filename="package://rastreator_description/mesh/imu.stl" scale="0.001 0.001 0.001"/>
      </geometry>
    </collision>
    <gravity>false</gravity>
    <!--VISUAL-->
    <visual>
      <geometry>
        <mesh filename="package://rastreator_description/mesh/imu.stl" scale="0.001 0.001 0.001"/>
      </geometry>
      <material name="dark"/>
    </visual>
    <!--
        <sensor name="rastreator_imu" type="imu">
          <always_on>true</always_on>
          <update_rate>${update_rate}</update_rate>
          <plugin name="imu" filename="libgazebo_ros_imu_sensor.so">
            <ros>
              <namespace>/sim</namespace>
              <argument>~/out:=imu_sim</argument>
            </ros>
          </plugin>
        </sensor>
        -->
  </link>
  <!--JOINT-->
  <joint name="sensor_imu_joint" type="fixed">
    <origin rpy="0 0.0 0" xyz="0.0 0.0 0"/>
    <child link="imu_link"/>
    <parent link="base_link"/>
  </joint>
  <!--**************************************************************-->
  <!--                    GAZEBO                                    -->
  <!--**************************************************************-->
  <gazebo reference="base_link">
    <material>Gazebo/DarkGrey</material>
  </gazebo>
  <gazebo reference="left_wheel_link">
    <material>Gazebo/FlatBlack</material>
    <mu1>0.9</mu1>
    <mu2>0.9</mu2>
    <kp>500000.0</kp>
    <kd>10.0</kd>
    <minDepth>0.001</minDepth>
    <maxVel>0.1</maxVel>
    <fdir1>1 0 0</fdir1>
  </gazebo>
  <gazebo reference="right_wheel_link">
    <material>Gazebo/FlatBlack</material>
    <mu1>0.9</mu1>
    <mu2>0.9</mu2>
    <kp>500000.0</kp>
    <kd>10.0</kd>
    <minDepth>0.001</minDepth>
    <maxVel>0.1</maxVel>
    <fdir1>1 0 0</fdir1>
  </gazebo>
  <gazebo reference="caster_front_link">
    <material>Gazebo/FlatBlack</material>
    <mu1>0.1</mu1>
    <mu2>0.1</mu2>
    <kp>1000000.0</kp>
    <kd>100.0</kd>
    <minDepth>0.001</minDepth>
    <maxVel>1.0</maxVel>
  </gazebo>
  <gazebo reference="sensor_laser">
    <material>Gazebo/FlatBlack</material>
  </gazebo>
  <gazebo reference="imu_link">
    <material>Gazebo/FlatBlack</material>
  </gazebo>
  <!--======= GAZEBO PLUGINS ===========-->
  <gazebo>
    <!--JOINT_STATES-->
    <plugin filename="libgazebo_ros_joint_state_publisher.so" name="plugin_joint_state">
      <ros>
        <!--<namespace>/sim</namespace>-->
        <argument>--ros-args --remap ~/out:=joint_states</argument>
      </ros>
      <update_rate>30</update_rate>
      <joint_name>wheel_left_joint</joint_name>
      <joint_name>wheel_right_joint</joint_name>
    </plugin>
    <!--DIFFERENTIAL DRIVE-->
    <plugin filename="libgazebo_ros_diff_drive.so" name="plugin_diff_drive">
      <ros>
        <!--<namespace>/sim</namespace>
          <argument>ros-args remap cmd_vel:=/sim/cmd_vel</argument>
          <argument>ros-args remap odom:=/sim/odom</argument>
          -->
      </ros>
      <update_rate>30</update_rate>
      <left_joint>wheel_left_joint</left_joint>
      <right_joint>wheel_right_joint</right_joint>
      <wheel_separation>0.16</wheel_separation>
      <wheel_diameter>0.065</wheel_diameter>
      <max_wheel_torque>10</max_wheel_torque>
      <max_wheel_acceleration>1.0</max_wheel_acceleration>
      <command_topic>cmd_vel</command_topic>
      <publish_odom>true</publish_odom>
      <publish_odom_tf>true</publish_odom_tf>
      <publish_wheel_tf>true</publish_wheel_tf>
      <odometry_topic>odom</odometry_topic>
      <odometry_frame>odom</odometry_frame>
      <robot_base_frame>base_footprint</robot_base_frame>
    </plugin>
    <plugin filename="libgazebo_ros_p3d.so" name="gazebo_ros_p3d">
      <ros>
        <!-- Add namespace and remap the default topic 
          <namespace>/sim</namespace>
          <argument>odom:=p3d_demo</argument>
          -->
      </ros>
      <!-- Replace camelCase elements with camel_case ones -->
      <body_name>base_footprint</body_name>
      <frame_name>base_footprint</frame_name>
      <update_rate>30</update_rate>
      <xyz_offsets>0 0 0</xyz_offsets>
      <rpy_offsets>0 0 0</rpy_offsets>
      <gaussian_noise>0</gaussian_noise>
    </plugin>
  </gazebo>
</robot>

